By using a try-catch block, you can make a decision on what to do with the exceptions that can occur.
Moreover, if you capture an exception with a catch, code can continue to execute after, which does not happen if the exception is not captured.

```
function executeSomeChecks(oAdditionalPropObjValue) {
    
    //previous code
    ...

    let sAdditionalProperty1, sAdditionalProperty2;
    try {
        const oObjValue = JSON.parse(oAdditionalPropObjValue);
        if (oObjValue["additionalProperties"] && oObjValue["additionalProperties"].length) {
	    sAdditionalProperty1 = oObjValue["additionalProperties"][0];
	    sAdditionalProperty2 = oObjValue["additionalProperties"][1]; 
        }
    } catch (err) {
        console.log(`Error while parsing JSON object: '${err}`);
        //The code can be executed forwards
        //or
        //The code can be stopped by throwing the err and return 
        throw err;
    }

    //following code
    ...

    return true;

}
```